Workbook

Sheet Sales budget performance manage
A1: Sales budget performance management
A2: Year 2026
A3: Budget/Results | B3: 46023 | F3: 46054 | J3: 46082 | N3: 46113 | R3: 46143 | V3: 46174 | AA3: =A3 -> Budget/Results | AB3: 46204 | AF3: 46236 | AJ3: 46268 | AN3: 46300 | AR3: 46332 | AV3: 46364 | AZ3: Total
B4: เป้าขาย | C4: คาดการณ์ ยอดขายล่าสุด | D4: Results ขายจริง 31/01/2569 | E4: Relative to budget | F4: เป้าขาย | G4: คาดการณ์ ยอดขายล่าสุด | H4: Results ขายจริง 26/02/2569 | I4: Relative to budget | J4: เป้าขาย | K4: คาดการณ์ ยอดขายล่าสุด | L4: Results ขายจริง31/03/2569 | M4: Relative to budget | N4: เป้าขาย | O4: คาดการณ์ ยอดขายล่าสุด | P4: Results ขายจริง 30/04/2569 | Q4: Relative to budget | R4: เป้าขาย | S4: คาดการณ์ ยอดขายล่าสุด | T4: Results ขายจริง 31/05/2569 | U4: Relative to budget | V4: เป้าขาย | W4: คาดการณ์ ยอดขายล่าสุด | X4: Results ขายจริง 30/06/2569 | Y4: Relative to budget | AB4: เป้าขาย | AC4: คาดการณ์ ยอดขายล่าสุด | AD4: Results ขายจริง 31/07/2569 | AE4: Relative to budget | AF4: เป้าขาย | AG4: คาดการณ์ ยอดขายล่าสุด | AH4: Results ขายจริง 31/08/2569 | AI4: Relative to budget | AJ4: เป้าขาย | AK4: คาดการณ์ ยอดขายล่าสุด | AL4: Results ขายจริง 17/09/2569 | AM4: Relative to budget | AN4: เป้าขาย | AO4: คาดการณ์ ยอดขายล่าสุด | AP4: Results ขายจริง | AQ4: Relative to budget | AR4: เป้าขาย | AS4: คาดการณ์ ยอดขายล่าสุด | AT4: Results ขายจริง | AU4: Relative to budget | AV4: เป้าขาย | AW4: คาดการณ์ ยอดขายล่าสุด | AX4: Results ขายจริง | AY4: Relative to budget | AZ4: เป้าขาย | BA4: คาดการณ์ ยอดขายล่าสุด | BB4: Results ขายจริง | BC4: Relative to budget
A5: Chain Restaurant | E5: =+IFERROR(D5/B5,"----") -> ---- | I5: =+IFERROR(H5/F5,"----") -> ---- | M5: =+IFERROR(L5/J5,"----") -> ---- | Q5: =+IFERROR(P5/N5,"----") -> ---- | U5: =+IFERROR(T5/R5,"----") -> ---- | Y5: =+IFERROR(X5/V5,"----") -> ---- | AA5: Chain Restaurant | AE5: =+IFERROR(AD5/AB5,"----") -> ---- | AI5: =+IFERROR(AH5/AF5,"----") -> ---- | AM5: =+IFERROR(AL5/AJ5,"----") -> ---- | AQ5: =+IFERROR(AP5/AN5,"----") -> ---- | AU5: =+IFERROR(AT5/AR5,"----") -> ---- | AY5: =+IFERROR(AX5/AV5,"----") -> ---- | AZ5: =B5+F5+J5+N5+R5+V5+AB5+AF5+AJ5+AN5+AR5+AV5 -> 0 | BA5: =C5+G5+K5+O5+S5+W5+AC5+AG5+AK5+AO5+AS5+AW5 -> 0 | BB5: =D5+H5+L5+P5+T5+X5+AD5+AH5+AL5+AP5+AT5+AX5 -> 0 | BC5: =+IFERROR(BB5/AZ5,"----") -> ----
A6: Sizzler | B6: 2000000 | C6: 1500000 | D6: 1456000 | E6: =+IFERROR(D6/B6,"----") -> 0.728 | F6: 2000000 | G6: 520000 | H6: 520000 | I6: =+IFERROR(H6/F6,"----") -> 0.26 | J6: 2000000 | K6: 1211250 | L6: 1211250 | M6: =+IFERROR(L6/J6,"----") -> 0.605625 | N6: 2000000 | O6: 912000 | P6: 912000 | Q6: =+IFERROR(P6/N6,"----") -> 0.456 | R6: 2500000 | S6: 700000 | T6: 672000 | U6: =+IFERROR(T6/R6,"----") -> 0.2688 | V6: 2500000 | W6: 1200000 | X6: 1200000 | Y6: =+IFERROR(X6/V6,"----") -> 0.48 | AA6: Sizzler | AB6: 2500000 | AC6: 2278500 | AD6: 2278500 | AE6: =+IFERROR(AD6/AB6,"----") -> 0.9114 | AF6: 2500000 | AG6: 2322000 | AH6: 2322000 | AI6: =+IFERROR(AH6/AF6,"----") -> 0.9288 | AJ6: 2500000 | AK6: 5226677.5 | AL6: 3152750 | AM6: =+IFERROR(AL6/AJ6,"----") -> 1.2611 | AN6: 2500000 | AO6: 3000000 | AQ6: =+IFERROR(AP6/AN6,"----") -> 0 | AR6: 2500000 | AS6: 4000000 | AU6: =+IFERROR(AT6/AR6,"----") -> 0 | AV6: 2500000 | AW6: 5000000 | AY6: =+IFERROR(AX6/AV6,"----") -> 0 | AZ6: =B6+F6+J6+N6+R6+V6+AB6+AF6+AJ6+AN6+AR6+AV6 -> 28000000 | BA6: =C6+G6+K6+O6+S6+W6+AC6+AG6+AK6+AO6+AS6+AW6 -> 27870428 | BB6: =D6+H6+L6+P6+T6+X6+AD6+AH6+AL6+AP6+AT6+AX6 -> 13724500 | BC6: =+IFERROR(BB6/AZ6,"----") -> 0.49016071
A7: Fuji | E7: =+IFERROR(D7/B7,"----") -> ---- | I7: =+IFERROR(H7/F7,"----") -> ---- | M7: =+IFERROR(L7/J7,"----") -> ---- | Q7: =+IFERROR(P7/N7,"----") -> ---- | U7: =+IFERROR(T7/R7,"----") -> ---- | Y7: =+IFERROR(X7/V7,"----") -> ---- | AA7: Fuji | AE7: =+IFERROR(AD7/AB7,"----") -> ---- | AI7: =+IFERROR(AH7/AF7,"----") -> ---- | AM7: =+IFERROR(AL7/AJ7,"----") -> ---- | AQ7: =+IFERROR(AP7/AN7,"----") -> ---- | AU7: =+IFERROR(AT7/AR7,"----") -> ---- | AY7: =+IFERROR(AX7/AV7,"----") -> ---- | AZ7: =B7+F7+J7+N7+R7+V7+AB7+AF7+AJ7+AN7+AR7+AV7 -> 0 | BA7: =C7+G7+K7+O7+S7+W7+AC7+AG7+AK7+AO7+AS7+AW7 -> 0 | BB7: =D7+H7+L7+P7+T7+X7+AD7+AH7+AL7+AP7+AT7+AX7 -> 0 | BC7: =+IFERROR(BB7/AZ7,"----") -> ----
A8: Zen | E8: =+IFERROR(D8/B8,"----") -> ---- | I8: =+IFERROR(H8/F8,"----") -> ---- | M8: =+IFERROR(L8/J8,"----") -> ---- | Q8: =+IFERROR(P8/N8,"----") -> ---- | U8: =+IFERROR(T8/R8,"----") -> ---- | Y8: =+IFERROR(X8/V8,"----") -> ---- | AA8: Zen | AE8: =+IFERROR(AD8/AB8,"----") -> ---- | AI8: =+IFERROR(AH8/AF8,"----") -> ---- | AM8: =+IFERROR(AL8/AJ8,"----") -> ---- | AQ8: =+IFERROR(AP8/AN8,"----") -> ---- | AU8: =+IFERROR(AT8/AR8,"----") -> ---- | AY8: =+IFERROR(AX8/AV8,"----") -> ---- | AZ8: =B8+F8+J8+N8+R8+V8+AB8+AF8+AJ8+AN8+AR8+AV8 -> 0 | BA8: =C8+G8+K8+O8+S8+W8+AC8+AG8+AK8+AO8+AS8+AW8 -> 0 | BB8: =D8+H8+L8+P8+T8+X8+AD8+AH8+AL8+AP8+AT8+AX8 -> 0 | BC8: =+IFERROR(BB8/AZ8,"----") -> ----
A9: ไดกิ | B9: 1000000 | C9: 700000 | D9: 545946.68 | E9: =+IFERROR(D9/B9,"----") -> 0.54594668 | F9: 1000000 | G9: 834794 | H9: 834794 | I9: =+IFERROR(H9/F9,"----") -> 0.834794 | J9: 1000000 | K9: 959690.4 | L9: 959690.4 | M9: =+IFERROR(L9/J9,"----") -> 0.9596904 | N9: 1000000 | O9: 1466560.3 | P9: 1466560.3 | Q9: =+IFERROR(P9/N9,"----") -> 1.4665603 | R9: 1200000 | S9: 2262387.9 | T9: 2262387.9 | U9: =+IFERROR(T9/R9,"----") -> 1.8853232 | V9: 1200000 | W9: 400000 | X9: 404551 | Y9: =+IFERROR(X9/V9,"----") -> 0.33712583 | AA9: ไดกิ | AB9: 1200000 | AC9: 1064000 | AD9: 1064000 | AE9: =+IFERROR(AD9/AB9,"----") -> 0.88666667 | AF9: 1200000 | AG9: 260000 | AH9: 260000 | AI9: =+IFERROR(AH9/AF9,"----") -> 0.21666667 | AJ9: 1200000 | AK9: 788000 | AL9: 584000 | AM9: =+IFERROR(AL9/AJ9,"----") -> 0.48666667 | AN9: 1200000 | AO9: 1000000 | AQ9: =+IFERROR(AP9/AN9,"----") -> 0 | AR9: 1200000 | AS9: 1000000 | AU9: =+IFERROR(AT9/AR9,"----") -> 0 | AV9: 1200000 | AW9: 1000000 | AY9: =+IFERROR(AX9/AV9,"----") -> 0 | AZ9: =B9+F9+J9+N9+R9+V9+AB9+AF9+AJ9+AN9+AR9+AV9 -> 13600000 | BA9: =C9+G9+K9+O9+S9+W9+AC9+AG9+AK9+AO9+AS9+AW9 -> 11735433 | BB9: =D9+H9+L9+P9+T9+X9+AD9+AH9+AL9+AP9+AT9+AX9 -> 8381930.3 | BC9: =+IFERROR(BB9/AZ9,"----") -> 0.6163184
A10: สามเสน | B10: 200000 | C10: 150000 | D10: 187801.65 | E10: =+IFERROR(D10/B10,"----") -> 0.93900825 | F10: 200000 | G10: 154639.35 | H10: 154639.35 | I10: =+IFERROR(H10/F10,"----") -> 0.77319675 | J10: 200000 | K10: 220179.6 | L10: 220179.6 | M10: =+IFERROR(L10/J10,"----") -> 1.100898 | N10: 200000 | O10: 222288.45 | P10: 222288.45 | Q10: =+IFERROR(P10/N10,"----") -> 1.1114422 | R10: 200000 | S10: 215550.05 | T10: 215550.05 | U10: =+IFERROR(T10/R10,"----") -> 1.0777503 | V10: 200000 | W10: 200000 | X10: 178116.1 | Y10: =+IFERROR(X10/V10,"----") -> 0.8905805 | AA10: สามเสน | AB10: 200000 | AC10: 266689.95 | AD10: 266689.95 | AE10: =+IFERROR(AD10/AB10,"----") -> 1.3334497 | AF10: 200000 | AG10: 199917.45 | AH10: 199917.45 | AI10: =+IFERROR(AH10/AF10,"----") -> 0.99958725 | AJ10: 200000 | AK10: 200000 | AL10: 172766.3 | AM10: =+IFERROR(AL10/AJ10,"----") -> 0.8638315 | AN10: 200000 | AO10: 200000 | AQ10: =+IFERROR(AP10/AN10,"----") -> 0 | AR10: 200000 | AS10: 200000 | AU10: =+IFERROR(AT10/AR10,"----") -> 0 | AV10: 200000 | AW10: 200000 | AY10: =+IFERROR(AX10/AV10,"----") -> 0 | AZ10: =B10+F10+J10+N10+R10+V10+AB10+AF10+AJ10+AN10+AR10+AV10 -> 2400000 | BA10: =C10+G10+K10+O10+S10+W10+AC10+AG10+AK10+AO10+AS10+AW10 -> 2429264.8 | BB10: =D10+H10+L10+P10+T10+X10+AD10+AH10+AL10+AP10+AT10+AX10 -> 1817948.9 | BC10: =+IFERROR(BB10/AZ10,"----") -> 0.75747871
A11: เดอะ ฟู๊ดซีเลคชั่น | B11: 150000 | C11: 65088.3 | D11: 65088.3 | E11: =+IFERROR(D11/B11,"----") -> 0.433922 | F11: 50000 | G11: 60288.9 | H11: 60288.9 | I11: =+IFERROR(H11/F11,"----") -> 1.205778 | J11: 50000 | K11: 68457 | L11: 68457 | M11: =+IFERROR(L11/J11,"----") -> 1.36914 | N11: 100000 | O11: 120549.3 | P11: 120549.3 | R11: 50000 | S11: 60157.8 | T11: 60157.8 | U11: =+IFERROR(T11/R11,"----") -> 1.203156 | V11: 50000 | W11: 56378.7 | X11: 56378.7 | AA11: เดอะ ฟู๊ดซีเลคชั่น | AB11: 50000 | AC11: 100000 | AD11: 56709.3 | AE11: =+IFERROR(AD11/AB11,"----") -> 1.134186 | AF11: 50000 | AG11: 61594.2 | AH11: 61594.2 | AI11: =+IFERROR(AH11/AF11,"----") -> 1.231884 | AJ11: 50000 | AN11: 50000 | AO11: 100000 | AQ11: =+IFERROR(AP11/AN11,"----") -> 0 | AR11: 50000 | AS11: 100000 | AU11: =+IFERROR(AT11/AR11,"----") -> 0 | AV11: 50000 | AW11: 100000 | AZ11: =B11+F11+J11+N11+R11+V11+AB11+AF11+AJ11+AN11+AR11+AV11 -> 750000 | BA11: =C11+G11+K11+O11+S11+W11+AC11+AG11+AK11+AO11+AS11+AW11 -> 892514.2 | BB11: =D11+H11+L11+P11+T11+X11+AD11+AH11+AL11+AP11+AT11+AX11 -> 549223.5 | BC11: =+IFERROR(BB11/AZ11,"----") -> 0.732298
A12: ฟู๊ดมี | B12: 150000 | C12: 43443.7 | D12: 43443.7 | E12: =+IFERROR(D12/B12,"----") -> 0.28962467 | F12: 100000 | I12: =+IFERROR(H12/F12,"----") -> 0 | J12: 100000 | K12: 10915 | L12: 10915 | M12: =+IFERROR(L12/J12,"----") -> 0.10915 | N12: 50000 | Q12: =+IFERROR(P12/N12,"----") -> 0 | R12: 100000 | S12: 50000 | T12: 25250 | U12: =+IFERROR(T12/R12,"----") -> 0.2525 | V12: 100000 | W12: 32235 | X12: 32235 | Y12: =+IFERROR(X12/V12,"----") -> 0.32235 | AA12: ฟู๊ดมี | AB12: 100000 | AC12: 31845 | AD12: 31845 | AE12: =+IFERROR(AD12/AB12,"----") -> 0.31845 | AF12: 100000 | AI12: =+IFERROR(AH12/AF12,"----") -> 0 | AJ12: 100000 | AM12: =+IFERROR(AL12/AJ12,"----") -> 0 | AN12: 100000 | AO12: 100000 | AQ12: =+IFERROR(AP12/AN12,"----") -> 0 | AR12: 100000 | AS12: 100000 | AU12: =+IFERROR(AT12/AR12,"----") -> 0 | AV12: 100000 | AW12: 100000 | AY12: =+IFERROR(AX12/AV12,"----") -> 0 | AZ12: =B12+F12+J12+N12+R12+V12+AB12+AF12+AJ12+AN12+AR12+AV12 -> 1200000 | BA12: =C12+G12+K12+O12+S12+W12+AC12+AG12+AK12+AO12+AS12+AW12 -> 468438.7 | BB12: =D12+H12+L12+P12+T12+X12+AD12+AH12+AL12+AP12+AT12+AX12 -> 143688.7 | BC12: =+IFERROR(BB12/AZ12,"----") -> 0.11974058
A13: เมก้ามูฟ | B13: 100000 | C13: 117502 | D13: 117502 | E13: =+IFERROR(D13/B13,"----") -> 1.17502 | F13: 100000 | G13: 98934 | H13: 98934 | I13: =+IFERROR(H13/F13,"----") -> 0.98934 | J13: 100000 | K13: 97878 | L13: 97878 | M13: =+IFERROR(L13/J13,"----") -> 0.97878 | N13: 100000 | O13: 138154.5 | P13: 138154.5 | Q13: =+IFERROR(P13/N13,"----") -> 1.381545 | R13: 100000 | S13: 41426 | T13: 41426 | U13: =+IFERROR(T13/R13,"----") -> 0.41426 | V13: 100000 | W13: 74800 | X13: 74800 | Y13: =+IFERROR(X13/V13,"----") -> 0.748 | AA13: เมก้ามูฟ | AB13: 100000 | AC13: 109637 | AD13: 109637 | AE13: =+IFERROR(AD13/AB13,"----") -> 1.09637 | AF13: 100000 | AG13: 70444 | AH13: 70444 | AI13: =+IFERROR(AH13/AF13,"----") -> 0.70444 | AJ13: 100000 | AK13: 100000 | AL13: 74123.5 | AM13: =+IFERROR(AL13/AJ13,"----") -> 0.741235 | AN13: 100000 | AO13: 100000 | AQ13: =+IFERROR(AP13/AN13,"----") -> 0 | AR13: 100000 | AS13: 100000 | AU13: =+IFERROR(AT13/AR13,"----") -> 0 | AV13: 100000 | AW13: 100000 | AY13: =+IFERROR(AX13/AV13,"----") -> 0 | AZ13: =B13+F13+J13+N13+R13+V13+AB13+AF13+AJ13+AN13+AR13+AV13 -> 1200000 | BA13: =C13+G13+K13+O13+S13+W13+AC13+AG13+AK13+AO13+AS13+AW13 -> 1148775.5 | BB13: =D13+H13+L13+P13+T13+X13+AD13+AH13+AL13+AP13+AT13+AX13 -> 822899 | BC13: =+IFERROR(BB13/AZ13,"----") -> 0.68574917
A14: แกลมเมอรัส | B14: 100000 | E14: =+IFERROR(D14/B14,"----") -> 0 | F14: 150000 | G14: 67002 | H14: 67002 | I14: =+IFERROR(H14/F14,"----") -> 0.44668 | J14: 150000 | K14: 136526 | L14: 136526 | M14: =+IFERROR(L14/J14,"----") -> 0.91017333 | N14: 150000 | Q14: =+IFERROR(P14/N14,"----") -> 0 | R14: 150000 | S14: 150000 | T14: 72520.5 | U14: =+IFERROR(T14/R14,"----") -> 0.48347 | V14: 150000 | Y14: =+IFERROR(X14/V14,"----") -> 0 | AA14: แกลมเมอรัส | AB14: 150000 | AC14: 68646.5 | AD14: 68646.5 | AE14: =+IFERROR(AD14/AB14,"----") -> 0.45764333 | AF14: 150000 | AG14: 68308.5 | AH14: 68308.5 | AI14: =+IFERROR(AH14/AF14,"----") -> 0.45539 | AJ14: 150000 | AM14: =+IFERROR(AL14/AJ14,"----") -> 0 | AN14: 150000 | AO14: 150000 | AQ14: =+IFERROR(AP14/AN14,"----") -> 0 | AR14: 150000 | AS14: 150000 | AU14: =+IFERROR(AT14/AR14,"----") -> 0 | AV14: 150000 | AW14: 150000 | AY14: =+IFERROR(AX14/AV14,"----") -> 0 | AZ14: =B14+F14+J14+N14+R14+V14+AB14+AF14+AJ14+AN14+AR14+AV14 -> 1750000 | BA14: =C14+G14+K14+O14+S14+W14+AC14+AG14+AK14+AO14+AS14+AW14 -> 940483 | BB14: =D14+H14+L14+P14+T14+X14+AD14+AH14+AL14+AP14+AT14+AX14 -> 413003.5 | BC14: =+IFERROR(BB14/AZ14,"----") -> 0.236002
A15: Oishi | E15: =+IFERROR(D15/B15,"----") -> ---- | I15: =+IFERROR(H15/F15,"----") -> ---- | M15: =+IFERROR(L15/J15,"----") -> ---- | Q15: =+IFERROR(P15/N15,"----") -> ---- | U15: =+IFERROR(T15/R15,"----") -> ---- | Y15: =+IFERROR(X15/V15,"----") -> ---- | AA15: Oishi | AE15: =+IFERROR(AD15/AB15,"----") -> ---- | AI15: =+IFERROR(AH15/AF15,"----") -> ---- | AM15: =+IFERROR(AL15/AJ15,"----") -> ---- | AQ15: =+IFERROR(AP15/AN15,"----") -> ---- | AU15: =+IFERROR(AT15/AR15,"----") -> ---- | AY15: =+IFERROR(AX15/AV15,"----") -> ---- | AZ15: =B15+F15+J15+N15+R15+V15+AB15+AF15+AJ15+AN15+AR15+AV15 -> 0 | BA15: =C15+G15+K15+O15+S15+W15+AC15+AG15+AK15+AO15+AS15+AW15 -> 0 | BB15: =D15+H15+L15+P15+T15+X15+AD15+AH15+AL15+AP15+AT15+AX15 -> 0 | BC15: =+IFERROR(BB15/AZ15,"----") -> ----
A16: BNN ตี๋น้อย | E16: =+IFERROR(D16/B16,"----") -> ---- | I16: =+IFERROR(H16/F16,"----") -> ---- | M16: =+IFERROR(L16/J16,"----") -> ---- | Q16: =+IFERROR(P16/N16,"----") -> ---- | U16: =+IFERROR(T16/R16,"----") -> ---- | Y16: =+IFERROR(X16/V16,"----") -> ---- | AA16: BNN ตี๋น้อย | AE16: =+IFERROR(AD16/AB16,"----") -> ---- | AI16: =+IFERROR(AH16/AF16,"----") -> ---- | AM16: =+IFERROR(AL16/AJ16,"----") -> ---- | AQ16: =+IFERROR(AP16/AN16,"----") -> ---- | AU16: =+IFERROR(AT16/AR16,"----") -> ---- | AY16: =+IFERROR(AX16/AV16,"----") -> ---- | AZ16: =B16+F16+J16+N16+R16+V16+AB16+AF16+AJ16+AN16+AR16+AV16 -> 0 | BA16: =C16+G16+K16+O16+S16+W16+AC16+AG16+AK16+AO16+AS16+AW16 -> 0 | BB16: =D16+H16+L16+P16+T16+X16+AD16+AH16+AL16+AP16+AT16+AX16 -> 0 | BC16: =+IFERROR(BB16/AZ16,"----") -> ----
A17: เชสเตอร์ฟู๊ด | B17: 70000 | C17: 70000 | D17: 63210.9 | E17: =+IFERROR(D17/B17,"----") -> 0.90301286 | F17: 70000 | G17: 67957.9 | H17: 67957.9 | I17: =+IFERROR(H17/F17,"----") -> 0.97082714 | J17: 50000 | K17: 67541.8 | L17: 67541.8 | M17: =+IFERROR(L17/J17,"----") -> 1.350836 | N17: 50000 | O17: 84067.3 | P17: 84067.3 | Q17: =+IFERROR(P17/N17,"----") -> 1.681346 | R17: 70000 | S17: 60000 | T17: 59639.6 | U17: =+IFERROR(T17/R17,"----") -> 0.85199429 | V17: 70000 | W17: 126415 | X17: 126415 | Y17: =+IFERROR(X17/V17,"----") -> 1.8059286 | AA17: เชสเตอร์ฟู๊ด | AB17: 70000 | AC17: 75000 | AD17: 75695 | AE17: =+IFERROR(AD17/AB17,"----") -> 1.0813571 | AF17: 70000 | AG17: 108000 | AH17: 108000 | AI17: =+IFERROR(AH17/AF17,"----") -> 1.5428571 | AJ17: 70000 | AK17: 108000 | AL17: 108000 | AM17: =+IFERROR(AL17/AJ17,"----") -> 1.5428571 | AN17: 70000 | AO17: 70000 | AQ17: =+IFERROR(AP17/AN17,"----") -> 0 | AR17: 70000 | AS17: 70000 | AU17: =+IFERROR(AT17/AR17,"----") -> 0 | AV17: 70000 | AW17: 70000 | AY17: =+IFERROR(AX17/AV17,"----") -> 0 | AZ17: =B17+F17+J17+N17+R17+V17+AB17+AF17+AJ17+AN17+AR17+AV17 -> 800000 | BA17: =C17+G17+K17+O17+S17+W17+AC17+AG17+AK17+AO17+AS17+AW17 -> 976982 | BB17: =D17+H17+L17+P17+T17+X17+AD17+AH17+AL17+AP17+AT17+AX17 -> 760527.5 | BC17: =+IFERROR(BB17/AZ17,"----") -> 0.95065937
A18: JCK | E18: =+IFERROR(D18/B18,"----") -> ---- | I18: =+IFERROR(H18/F18,"----") -> ---- | M18: =+IFERROR(L18/J18,"----") -> ---- | Q18: =+IFERROR(P18/N18,"----") -> ---- | U18: =+IFERROR(T18/R18,"----") -> ---- | Y18: =+IFERROR(X18/V18,"----") -> ---- | AA18: JCK | AE18: =+IFERROR(AD18/AB18,"----") -> ---- | AM18: =+IFERROR(AL18/AJ18,"----") -> ---- | AQ18: =+IFERROR(AP18/AN18,"----") -> ---- | AU18: =+IFERROR(AT18/AR18,"----") -> ---- | AY18: =+IFERROR(AX18/AV18,"----") -> ---- | AZ18: =B18+F18+J18+N18+R18+V18+AB18+AF18+AJ18+AN18+AR18+AV18 -> 0 | BA18: =C18+G18+K18+O18+S18+W18+AC18+AG18+AK18+AO18+AS18+AW18 -> 0 | BB18: =D18+H18+L18+P18+T18+X18+AD18+AH18+AL18+AP18+AT18+AX18 -> 0 | BC18: =+IFERROR(BB18/AZ18,"----") -> ----
A19: CRG | B19: 500000 | C19: 50400 | D19: 50400 | E19: =+IFERROR(D19/B19,"----") -> 0.1008 | F19: 500000 | G19: 67200 | H19: 67200 | I19: =+IFERROR(H19/F19,"----") -> 0.1344 | J19: 500000 | K19: 57000 | L19: 57000 | M19: =+IFERROR(L19/J19,"----") -> 0.114 | N19: 500000 | O19: 691080 | P19: 691080 | Q19: =+IFERROR(P19/N19,"----") -> 1.38216 | R19: 500000 | S19: 57000 | T19: 57000 | U19: =+IFERROR(T19/R19,"----") -> 0.114 | V19: 500000 | W19: 117900 | X19: 117900 | Y19: =+IFERROR(X19/V19,"----") -> 0.2358 | AA19: CRG | AB19: 500000 | AC19: 84000 | AD19: 84000 | AE19: =+IFERROR(AD19/AB19,"----") -> 0.168 | AF19: 500000 | AG19: 90000 | AH19: 90000 | AI19: =+IFERROR(AH19/AF19,"----") -> 0.18 | AJ19: 500000 | AK19: 50000 | AM19: =+IFERROR(AL19/AJ19,"----") -> 0 | AN19: 500000 | AO19: 200000 | AQ19: =+IFERROR(AP19/AN19,"----") -> 0 | AR19: 500000 | AS19: 200000 | AU19: =+IFERROR(AT19/AR19,"----") -> 0 | AV19: 500000 | AW19: 200000 | AY19: =+IFERROR(AX19/AV19,"----") -> 0 | AZ19: =B19+F19+J19+N19+R19+V19+AB19+AF19+AJ19+AN19+AR19+AV19 -> 6000000 | BA19: =C19+G19+K19+O19+S19+W19+AC19+AG19+AK19+AO19+AS19+AW19 -> 1864580 | BB19: =D19+H19+L19+P19+T19+X19+AD19+AH19+AL19+AP19+AT19+AX19 -> 1214580 | BC19: =+IFERROR(BB19/AZ19,"----") -> 0.20243
A20: Zaab Eli | B20: 300000 | C20: 200000 | D20: 168918.75 | E20: =+IFERROR(D20/B20,"----") -> 0.5630625 | F20: 300000 | G20: 459112.5 | H20: 459112.5 | I20: =+IFERROR(H20/F20,"----") -> 1.530375 | J20: 300000 | K20: 402672.45 | L20: 402672.45 | M20: =+IFERROR(L20/J20,"----") -> 1.3422415 | N20: 300000 | O20: 564569.9 | P20: 564569.9 | Q20: =+IFERROR(P20/N20,"----") -> 1.8818997 | R20: 300000 | S20: 280350 | T20: 280350 | U20: =+IFERROR(T20/R20,"----") -> 0.9345 | V20: 300000 | W20: 341040 | X20: 341040 | Y20: =+IFERROR(X20/V20,"----") -> 1.1368 | AA20: Zaab Eli | AB20: 300000 | AC20: 509815.2 | AD20: 509815.2 | AF20: 300000 | AG20: 430000 | AH20: 443746.8 | AI20: =+IFERROR(AH20/AF20,"----") -> 1.479156 | AJ20: 300000 | AK20: 300000 | AL20: 202920 | AM20: =+IFERROR(AL20/AJ20,"----") -> 0.6764 | AN20: 300000 | AO20: 300000 | AQ20: =+IFERROR(AP20/AN20,"----") -> 0 | AR20: 300000 | AS20: 300000 | AU20: =+IFERROR(AT20/AR20,"----") -> 0 | AV20: 300000 | AW20: 300000 | AY20: =+IFERROR(AX20/AV20,"----") -> 0 | AZ20: =B20+F20+J20+N20+R20+V20+AB20+AF20+AJ20+AN20+AR20+AV20 -> 3600000 | BA20: =C20+G20+K20+O20+S20+W20+AC20+AG20+AK20+AO20+AS20+AW20 -> 4387560.1 | BB20: =D20+H20+L20+P20+T20+X20+AD20+AH20+AL20+AP20+AT20+AX20 -> 3373145.6 | BC20: =+IFERROR(BB20/AZ20,"----") -> 0.93698489
A21: คำพูน | B21: 200000 | C21: 223195 | D21: 223195 | E21: =+IFERROR(D21/B21,"----") -> 1.115975 | F21: 200000 | G21: 189210 | H21: 189210 | I21: =+IFERROR(H21/F21,"----") -> 0.94605 | J21: 200000 | K21: 264838 | L21: 264838 | M21: =+IFERROR(L21/J21,"----") -> 1.32419 | N21: 200000 | O21: 182273 | P21: 182273 | Q21: =+IFERROR(P21/N21,"----") -> 0.911365 | R21: 200000 | S21: 267659 | T21: 267659 | U21: =+IFERROR(T21/R21,"----") -> 1.338295 | V21: 200000 | W21: 156996.4 | X21: 156996.4 | Y21: =+IFERROR(X21/V21,"----") -> 0.784982 | AA21: other (อีซี่สเต็ก,คิงคอง,ซูกิซิ,เอสบีแอลจี,สีฟ้า,นิกิวาอิ,ราชารส,ชาบูเชน,ชาชิมิ,เดอะฮิโร๊ะ,อีชิลี่,เซ็นทรัล เรสตอรองส์ | AB21: 200000 | AC21: 216591 | AD21: 216591 | AE21: =+IFERROR(AD21/AB21,"----") -> 1.082955 | AF21: 200000 | AG21: 268939.3 | AH21: 268939.3 | AI21: =+IFERROR(AH21/AF21,"----") -> 1.3446965 | AJ21: 200000 | AK21: 280000 | AL21: 167637.2 | AM21: =+IFERROR(AL21/AJ21,"----") -> 0.838186 | AN21: 200000 | AO21: 250000 | AQ21: =+IFERROR(AP21/AN21,"----") -> 0 | AR21: 200000 | AS21: 250000 | AU21: =+IFERROR(AT21/AR21,"----") -> 0 | AV21: 200000 | AW21: 250000 | AY21: =+IFERROR(AX21/AV21,"----") -> 0 | AZ21: =B21+F21+J21+N21+R21+V21+AB21+AF21+AJ21+AN21+AR21+AV21 -> 2400000 | BA21: =C21+G21+K21+O21+S21+W21+AC21+AG21+AK21+AO21+AS21+AW21 -> 2799701.7 | BB21: =D21+H21+L21+P21+T21+X21+AD21+AH21+AL21+AP21+AT21+AX21 -> 1937338.9 | BC21: =+IFERROR(BB21/AZ21,"----") -> 0.80722454
A22: other (อีซี่สเต็ก,คิงคอง,ซูกิซิ,เอสบีแอลจี,สีฟ้า,นิกิวาอิ,ราชารส,ชาบูเชน,ชาชิมิ,เดอะฮิโร๊ะ,,บอนชอน,นิตยาไก่ย่าง,เดอะสเต๊กแอนมอร์,ฉันเรสเตอรองท์,แจลลุกซ์ | B22: 200000 | C22: 49140 | D22: 49140 | E22: =+IFERROR(D22/B22,"----") -> 0.2457 | F22: 150000 | G22: 28800 | H22: 28800 | I22: =+IFERROR(H22/F22,"----") -> 0.192 | J22: 100000 | K22: 28800 | L22: 28800 | M22: =+IFERROR(L22/J22,"----") -> 0.288 | N22: 100000 | O22: 44523 | P22: 44523 | Q22: =+IFERROR(P22/N22,"----") -> 0.44523 | R22: 100000 | U22: =+IFERROR(T22/R22,"----") -> 0 | V22: 100000 | W22: 56817.6 | X22: 56817.6 | Y22: =+IFERROR(X22/V22,"----") -> 0.568176 | AA22: other (อีซี่สเต็ก,คิงคอง,ซูกิซิ,เอสบีแอลจี,สีฟ้า,นิกิวาอิ,ราชารส,ชาบูเชน,ชาชิมิ,เดอะฮิโร๊ะ,อีชิลี่,เซ็นทรัล เรสตอรองส์ | AB22: 100000 | AC22: =375250+486000+16358.4 -> 877608.4 | AD22: =375250+486000+16358.4 -> 877608.4 | AE22: =+IFERROR(AD22/AB22,"----") -> 8.776084 | AF22: 100000 | AG22: 1172624 | AH22: 1172624 | AI22: =+IFERROR(AH22/AF22,"----") -> 11.72624 | AJ22: 100000 | AK22: 1200000 | AL22: 934548.9 | AM22: =+IFERROR(AL22/AJ22,"----") -> 9.345489 | AN22: 100000 | AO22: 500000 | AQ22: =+IFERROR(AP22/AN22,"----") -> 0 | AR22: 100000 | AS22: 500000 | AU22: =+IFERROR(AT22/AR22,"----") -> 0 | AV22: 100000 | AW22: 500000 | AY22: =+IFERROR(AX22/AV22,"----") -> 0 | AZ22: =B22+F22+J22+N22+R22+V22+AB22+AF22+AJ22+AN22+AR22+AV22 -> 1350000 | BA22: =C22+G22+K22+O22+S22+W22+AC22+AG22+AK22+AO22+AS22+AW22 -> 4958313 | BB22: =D22+H22+L22+P22+T22+X22+AD22+AH22+AL22+AP22+AT22+AX22 -> 3192861.9 | BC22: =+IFERROR(BB22/AZ22,"----") -> 2.3650829
A23: Supermarket | E23: =+IFERROR(D23/B23,"----") -> ---- | I23: =+IFERROR(H23/F23,"----") -> ---- | M23: =+IFERROR(L23/J23,"----") -> ---- | Q23: =+IFERROR(P23/N23,"----") -> ---- | U23: =+IFERROR(T23/R23,"----") -> ---- | Y23: =+IFERROR(X23/V23,"----") -> ---- | AA23: Supermarket | AE23: =+IFERROR(AD23/AB23,"----") -> ---- | AI23: =+IFERROR(AH23/AF23,"----") -> ---- | AM23: =+IFERROR(AL23/AJ23,"----") -> ---- | AQ23: =+IFERROR(AP23/AN23,"----") -> ---- | AU23: =+IFERROR(AT23/AR23,"----") -> ---- | AY23: =+IFERROR(AX23/AV23,"----") -> ---- | AZ23: =B23+F23+J23+N23+R23+V23+AB23+AF23+AJ23+AN23+AR23+AV23 -> 0 | BA23: =C23+G23+K23+O23+S23+W23+AC23+AG23+AK23+AO23+AS23+AW23 -> 0 | BB23: =D23+H23+L23+P23+T23+X23+AD23+AH23+AL23+AP23+AT23+AX23 -> 0 | BC23: =+IFERROR(BB23/AZ23,"----") -> ----
A24: Donki | B24: 500000 | C24: 600000 | D24: 649812 | E24: =+IFERROR(D24/B24,"----") -> 1.299624 | F24: 500000 | G24: 492032 | H24: 492032 | I24: =+IFERROR(H24/F24,"----") -> 0.984064 | J24: 400000 | K24: 913455 | L24: 913455 | M24: =+IFERROR(L24/J24,"----") -> 2.2836375 | N24: 400000 | O24: 1028007 | P24: 1028007 | Q24: =+IFERROR(P24/N24,"----") -> 2.5700175 | R24: 500000 | S24: 459340 | T24: 459340 | U24: =+IFERROR(T24/R24,"----") -> 0.91868 | V24: 500000 | W24: 372542 | X24: 372542 | Y24: =+IFERROR(X24/V24,"----") -> 0.745084 | AA24: Donki | AB24: 500000 | AC24: 700000 | AD24: 659202 | AE24: =+IFERROR(AD24/AB24,"----") -> 1.318404 | AF24: 500000 | AG24: 577217 | AH24: 577217 | AI24: =+IFERROR(AH24/AF24,"----") -> 1.154434 | AJ24: 500000 | AK24: 600000 | AL24: 384687 | AM24: =+IFERROR(AL24/AJ24,"----") -> 0.769374 | AN24: 500000 | AO24: 700000 | AQ24: =+IFERROR(AP24/AN24,"----") -> 0 | AR24: 500000 | AS24: 800000 | AU24: =+IFERROR(AT24/AR24,"----") -> 0 | AV24: 500000 | AW24: 1000000 | AY24: =+IFERROR(AX24/AV24,"----") -> 0 | AZ24: =B24+F24+J24+N24+R24+V24+AB24+AF24+AJ24+AN24+AR24+AV24 -> 5800000 | BA24: =C24+G24+K24+O24+S24+W24+AC24+AG24+AK24+AO24+AS24+AW24 -> 8242593 | BB24: =D24+H24+L24+P24+T24+X24+AD24+AH24+AL24+AP24+AT24+AX24 -> 5536294 | BC24: =+IFERROR(BB24/AZ24,"----") -> 0.95453345
A25: Themall | E25: =+IFERROR(D25/B25,"----") -> ---- | I25: =+IFERROR(H25/F25,"----") -> ---- | K25: 14851.05 | L25: 14851.05 | M25: =+IFERROR(L25/J25,"----") -> ---- | O25: 603.45 | P25: 603.45 | Q25: =+IFERROR(P25/N25,"----") -> ---- | R25: 100000 | U25: =+IFERROR(T25/R25,"----") -> 0 | Y25: =+IFERROR(X25/V25,"----") -> ---- | AA25: Themall | AE25: =+IFERROR(AD25/AB25,"----") -> ---- | AI25: =+IFERROR(AH25/AF25,"----") -> ---- | AM25: =+IFERROR(AL25/AJ25,"----") -> ---- | AQ25: =+IFERROR(AP25/AN25,"----") -> ---- | AU25: =+IFERROR(AT25/AR25,"----") -> ---- | AY25: =+IFERROR(AX25/AV25,"----") -> ---- | AZ25: =B25+F25+J25+N25+R25+V25+AB25+AF25+AJ25+AN25+AR25+AV25 -> 100000 | BA25: =C25+G25+K25+O25+S25+W25+AC25+AG25+AK25+AO25+AS25+AW25 -> 15454.5 | BB25: =D25+H25+L25+P25+T25+X25+AD25+AH25+AL25+AP25+AT25+AX25 -> 15454.5 | BC25: =+IFERROR(BB25/AZ25,"----") -> 0.154545
A26: Makro | B26: 3000000 | C26: 2500000 | D26: 2602656.2 | E26: =+IFERROR(D26/B26,"----") -> 0.86755207 | F26: 3000000 | G26: 2151812 | H26: 2151812 | I26: =+IFERROR(H26/F26,"----") -> 0.71727068 | J26: 2000000 | K26: 3712128 | L26: 3712128 | M26: =+IFERROR(L26/J26,"----") -> 1.856064 | N26: 2000000 | O26: 1253592.7 | P26: 1253592.7 | Q26: =+IFERROR(P26/N26,"----") -> 0.62679634 | R26: 2500000 | S26: 1825594.3 | T26: 1825594.3 | U26: =+IFERROR(T26/R26,"----") -> 0.73023771 | V26: 2500000 | W26: 2088902.5 | X26: 2088902.5 | Y26: =+IFERROR(X26/V26,"----") -> 0.835561 | AA26: Makro | AB26: 2500000 | AC26: 2751905 | AD26: 2751905 | AE26: =+IFERROR(AD26/AB26,"----") -> 1.100762 | AF26: 2500000 | AG26: 3026469.8 | AH26: 3026469.8 | AI26: =+IFERROR(AH26/AF26,"----") -> 1.2105879 | AJ26: 2500000 | AK26: 3000000 | AL26: 1410376.4 | AM26: =+IFERROR(AL26/AJ26,"----") -> 0.56415056 | AN26: 2500000 | AO26: 3000000 | AQ26: =+IFERROR(AP26/AN26,"----") -> 0 | AR26: 2500000 | AS26: 3500000 | AU26: =+IFERROR(AT26/AR26,"----") -> 0 | AV26: 2500000 | AW26: 4000000 | AY26: =+IFERROR(AX26/AV26,"----") -> 0 | AZ26: =B26+F26+J26+N26+R26+V26+AB26+AF26+AJ26+AN26+AR26+AV26 -> 30000000 | BA26: =C26+G26+K26+O26+S26+W26+AC26+AG26+AK26+AO26+AS26+AW26 -> 32810404 | BB26: =D26+H26+L26+P26+T26+X26+AD26+AH26+AL26+AP26+AT26+AX26 -> 20823437 | BC26: =+IFERROR(BB26/AZ26,"----") -> 0.69411456
A27: Rimping | B27: 150000 | C27: 128735.45 | D27: 128735.45 | E27: =+IFERROR(D27/B27,"----") -> 0.85823633 | F27: 150000 | G27: 95612.06 | H27: 95612.06 | I27: =+IFERROR(H27/F27,"----") -> 0.63741373 | J27: 150000 | K27: 71436.78 | L27: 71436.78 | M27: =+IFERROR(L27/J27,"----") -> 0.4762452 | N27: 150000 | O27: 46018.33 | P27: 46018.33 | Q27: =+IFERROR(P27/N27,"----") -> 0.30678887 | R27: 150000 | S27: 55836.47 | T27: 55836.47 | U27: =+IFERROR(T27/R27,"----") -> 0.37224313 | V27: 150000 | W27: 50829.07 | X27: 50829.07 | Y27: =+IFERROR(X27/V27,"----") -> 0.33886047 | AA27: Rimping | AB27: 150000 | AC27: 39574.72 | AD27: 39574.72 | AE27: =+IFERROR(AD27/AB27,"----") -> 0.26383147 | AF27: 150000 | AG27: 63017.07 | AH27: 63017.07 | AI27: =+IFERROR(AH27/AF27,"----") -> 0.4201138 | AJ27: 150000 | AK27: 77824.23 | AL27: 77824.23 | AM27: =+IFERROR(AL27/AJ27,"----") -> 0.5188282 | AN27: 150000 | AO27: 100000 | AQ27: =+IFERROR(AP27/AN27,"----") -> 0 | AR27: 150000 | AS27: 100000 | AU27: =+IFERROR(AT27/AR27,"----") -> 0 | AV27: 150000 | AW27: 100000 | AY27: =+IFERROR(AX27/AV27,"----") -> 0 | AZ27: =B27+F27+J27+N27+R27+V27+AB27+AF27+AJ27+AN27+AR27+AV27 -> 1800000 | BA27: =C27+G27+K27+O27+S27+W27+AC27+AG27+AK27+AO27+AS27+AW27 -> 928884.18 | BB27: =D27+H27+L27+P27+T27+X27+AD27+AH27+AL27+AP27+AT27+AX27 -> 628884.18 | BC27: =+IFERROR(BB27/AZ27,"----") -> 0.3493801
A28: Maxvalue | E28: =+IFERROR(D28/B28,"----") -> ---- | I28: =+IFERROR(H28/F28,"----") -> ---- | M28: =+IFERROR(L28/J28,"----") -> ---- | Q28: =+IFERROR(P28/N28,"----") -> ---- | U28: =+IFERROR(T28/R28,"----") -> ---- | Y28: =+IFERROR(X28/V28,"----") -> ---- | AA28: Maxvalue | AE28: =+IFERROR(AD28/AB28,"----") -> ---- | AI28: =+IFERROR(AH28/AF28,"----") -> ---- | AM28: =+IFERROR(AL28/AJ28,"----") -> ---- | AQ28: =+IFERROR(AP28/AN28,"----") -> ---- | AU28: =+IFERROR(AT28/AR28,"----") -> ---- | AY28: =+IFERROR(AX28/AV28,"----") -> ---- | AZ28: =B28+F28+J28+N28+R28+V28+AB28+AF28+AJ28+AN28+AR28+AV28 -> 0 | BA28: =C28+G28+K28+O28+S28+W28+AC28+AG28+AK28+AO28+AS28+AW28 -> 0 | BB28: =D28+H28+L28+P28+T28+X28+AD28+AH28+AL28+AP28+AT28+AX28 -> 0 | BC28: =+IFERROR(BB28/AZ28,"----") -> ----
A29: Central food | E29: =+IFERROR(D29/B29,"----") -> ---- | I29: =+IFERROR(H29/F29,"----") -> ---- | M29: =+IFERROR(L29/J29,"----") -> ---- | Q29: =+IFERROR(P29/N29,"----") -> ---- | U29: =+IFERROR(T29/R29,"----") -> ---- | Y29: =+IFERROR(#REF!/V29,"----") -> ---- | AA29: Central food | AE29: =+IFERROR(AD29/AB29,"----") -> ---- | AI29: =+IFERROR(AH29/AF29,"----") -> ---- | AM29: =+IFERROR(AL29/AJ29,"----") -> ---- | AQ29: =+IFERROR(AP29/AN29,"----") -> ---- | AU29: =+IFERROR(AT29/AR29,"----") -> ---- | AY29: =+IFERROR(AX29/AV29,"----") -> ---- | AZ29: =B29+F29+J29+N29+R29+V29+AB29+AF29+AJ29+AN29+AR29+AV29 -> 0 | BA29: =C29+G29+K29+O29+S29+W29+AC29+AG29+AK29+AO29+AS29+AW29 -> 0 | BB29: =D29+H29+L29+P29+T29+X29+AD29+AH29+AL29+AP29+AT29+AX29 -> 0 | BC29: =+IFERROR(BB29/AZ29,"----") -> ----
A30: Other (เจแวลู,ยูเนี่ยนพี,อาร์พีแอล) | B30: 10000 | C30: 10000 | D30: 3066.23 | E30: =+IFERROR(D30/B30,"----") -> 0.306623 | F30: 10000 | G30: 13877.64 | H30: 13877.64 | I30: =+IFERROR(H30/F30,"----") -> 1.387764 | J30: 10000 | K30: 21623.75 | L30: 21623.75 | M30: =+IFERROR(L30/J30,"----") -> 2.162375 | N30: 10000 | O30: 5610 | P30: 5610 | Q30: =+IFERROR(P30/N30,"----") -> 0.561 | R30: 10000 | S30: 10000 | T30: 5960 | U30: =+IFERROR(T30/R30,"----") -> 0.596 | V30: 10000 | W30: 12796 | X30: 12796 | Y30: =+IFERROR(X29/V30,"----") -> 0 | AA30: Other (เจแวลู,ยูเนี่ยนพี) | AB30: 10000 | AC30: 15000 | AD30: 14964 | AE30: =+IFERROR(AD30/AB30,"----") -> 1.4964 | AF30: 10000 | AG30: 20070 | AH30: 20070 | AI30: =+IFERROR(AH30/AF30,"----") -> 2.007 | AJ30: 10000 | AK30: 20000 | AL30: 10314 | AM30: =+IFERROR(AL30/AJ30,"----") -> 1.0314 | AN30: 10000 | AO30: 10000 | AQ30: =+IFERROR(AP30/AN30,"----") -> 0 | AR30: 10000 | AS30: 10000 | AU30: =+IFERROR(AT30/AR30,"----") -> 0 | AV30: 10000 | AW30: 10000 | AY30: =+IFERROR(AX30/AV30,"----") -> 0 | AZ30: =B30+F30+J30+N30+R30+V30+AB30+AF30+AJ30+AN30+AR30+AV30 -> 120000 | BA30: =C30+G30+K30+O30+S30+W30+AC30+AG30+AK30+AO30+AS30+AW30 -> 158977.39 | BB30: =D30+H30+L30+P30+T30+X30+AD30+AH30+AL30+AP30+AT30+AX30 -> 108281.62 | BC30: =+IFERROR(BB30/AZ30,"----") -> 0.90234683
A31: Agency | E31: =+IFERROR(D31/B31,"----") -> ---- | I31: =+IFERROR(H31/F31,"----") -> ---- | M31: =+IFERROR(L31/J31,"----") -> ---- | Q31: =+IFERROR(P31/N31,"----") -> ---- | U31: =+IFERROR(T31/R31,"----") -> ---- | Y31: =+IFERROR(X31/V31,"----") -> ---- | AA31: Agency | AE31: =+IFERROR(AD31/AB31,"----") -> ---- | AI31: =+IFERROR(AH31/AF31,"----") -> ---- | AM31: =+IFERROR(AL31/AJ31,"----") -> ---- | AQ31: =+IFERROR(AP31/AN31,"----") -> ---- | AU31: =+IFERROR(AT31/AR31,"----") -> ---- | AY31: =+IFERROR(AX31/AV31,"----") -> ---- | AZ31: =B31+F31+J31+N31+R31+V31+AB31+AF31+AJ31+AN31+AR31+AV31 -> 0 | BA31: =C31+G31+K31+O31+S31+W31+AC31+AG31+AK31+AO31+AS31+AW31 -> 0 | BB31: =D31+H31+L31+P31+T31+X31+AD31+AH31+AL31+AP31+AT31+AX31 -> 0 | BC31: =+IFERROR(BB31/AZ31,"----") -> ----
A32: Panfood | B32: 500000 | C32: 181674.1 | D32: 181674.1 | E32: =+IFERROR(D32/B32,"----") -> 0.3633482 | F32: 500000 | G32: 542511.7 | H32: 542511.7 | I32: =+IFERROR(H32/F32,"----") -> 1.0850234 | J32: 500000 | K32: 240663.5 | L32: 240663.5 | M32: =+IFERROR(L32/J32,"----") -> 0.481327 | N32: 500000 | O32: 469387.2 | P32: 469387.2 | Q32: =+IFERROR(P32/N32,"----") -> 0.9387744 | R32: 300000 | S32: 406898.5 | T32: 406898.5 | U32: =+IFERROR(T32/R32,"----") -> 1.3563283 | V32: 300000 | W32: 44574 | X32: 44574 | Y32: =+IFERROR(X32/V32,"----") -> 0.14858 | AA32: Panfood | AB32: 300000 | AC32: 422701.7 | AD32: 422701.7 | AE32: =+IFERROR(AD32/AB32,"----") -> 1.4090057 | AF32: 300000 | AG32: 398179.4 | AH32: 398179.4 | AI32: =+IFERROR(AH32/AF32,"----") -> 1.3272647 | AJ32: 300000 | AK32: 400000 | AM32: =+IFERROR(AL32/AJ32,"----") -> 0 | AN32: 300000 | AO32: 400000 | AQ32: =+IFERROR(AP32/AN32,"----") -> 0 | AR32: 300000 | AS32: 400000 | AU32: =+IFERROR(AT32/AR32,"----") -> 0 | AV32: 300000 | AW32: 400000 | AY32: =+IFERROR(AX32/AV32,"----") -> 0 | AZ32: =B32+F32+J32+N32+R32+V32+AB32+AF32+AJ32+AN32+AR32+AV32 -> 4400000 | BA32: =C32+G32+K32+O32+S32+W32+AC32+AG32+AK32+AO32+AS32+AW32 -> 4306590.1 | BB32: =D32+H32+L32+P32+T32+X32+AD32+AH32+AL32+AP32+AT32+AX32 -> 2706590.1 | BC32: =+IFERROR(BB32/AZ32,"----") -> 0.61513411
A33: Siam Food | E33: =+IFERROR(D33/B33,"----") -> ---- | I33: =+IFERROR(H33/F33,"----") -> ---- | M33: =+IFERROR(L33/J33,"----") -> ---- | Q33: =+IFERROR(P33/N33,"----") -> ---- | U33: =+IFERROR(T33/R33,"----") -> ---- | Y33: =+IFERROR(X33/V33,"----") -> ---- | AA33: Siam Food | AE33: =+IFERROR(AD33/AB33,"----") -> ---- | AI33: =+IFERROR(AH33/AF33,"----") -> ---- | AM33: =+IFERROR(AL33/AJ33,"----") -> ---- | AQ33: =+IFERROR(AP33/AN33,"----") -> ---- | AU33: =+IFERROR(AT33/AR33,"----") -> ---- | AY33: =+IFERROR(AX33/AV33,"----") -> ---- | AZ33: =B33+F33+J33+N33+R33+V33+AB33+AF33+AJ33+AN33+AR33+AV33 -> 0 | BA33: =C33+G33+K33+O33+S33+W33+AC33+AG33+AK33+AO33+AS33+AW33 -> 0 | BB33: =D33+H33+L33+P33+T33+X33+AD33+AH33+AL33+AP33+AT33+AX33 -> 0 | BC33: =+IFERROR(BB33/AZ33,"----") -> ----
A34: C.T.I. | B34: 500000 | C34: 380000 | D34: 374584.4 | E34: =+IFERROR(D34/B34,"----") -> 0.7491688 | F34: 500000 | G34: 719513.2 | H34: 719513.2 | I34: =+IFERROR(H34/F34,"----") -> 1.4390264 | J34: 500000 | K34: 788304 | L34: 788304 | M34: =+IFERROR(L34/J34,"----") -> 1.576608 | N34: 500000 | O34: 673552.4 | P34: 673552.4 | Q34: =+IFERROR(P34/N34,"----") -> 1.3471048 | R34: 500000 | S34: 309774 | T34: 309774 | U34: =+IFERROR(T34/R34,"----") -> 0.619548 | V34: 500000 | W34: 600000 | X34: 547572 | Y34: =+IFERROR(X34/V34,"----") -> 1.095144 | AA34: C.T.I. | AB34: 500000 | AC34: 700000 | AD34: 678708 | AE34: =+IFERROR(AD34/AB34,"----") -> 1.357416 | AF34: 500000 | AG34: 856507.6 | AH34: 856507.6 | AI34: =+IFERROR(AH34/AF34,"----") -> 1.7130152 | AJ34: 500000 | AK34: 600000 | AM34: =+IFERROR(AL34/AJ34,"----") -> 0 | AN34: 500000 | AO34: 700000 | AQ34: =+IFERROR(AP34/AN34,"----") -> 0 | AR34: 500000 | AS34: 800000 | AU34: =+IFERROR(AT34/AR34,"----") -> 0 | AV34: 500000 | AW34: 800000 | AY34: =+IFERROR(AX34/AV34,"----") -> 0 | AZ34: =B34+F34+J34+N34+R34+V34+AB34+AF34+AJ34+AN34+AR34+AV34 -> 6000000 | BA34: =C34+G34+K34+O34+S34+W34+AC34+AG34+AK34+AO34+AS34+AW34 -> 7927651.2 | BB34: =D34+H34+L34+P34+T34+X34+AD34+AH34+AL34+AP34+AT34+AX34 -> 4948515.6 | BC34: =+IFERROR(BB34/AZ34,"----") -> 0.8247526
A35: KK &K | E35: =+IFERROR(D35/B35,"----") -> ---- | I35: =+IFERROR(H35/F35,"----") -> ---- | M35: =+IFERROR(L35/J35,"----") -> ---- | Q35: =+IFERROR(P35/N35,"----") -> ---- | U35: =+IFERROR(#REF!/R35,"----") -> ---- | Y35: =+IFERROR(X35/V35,"----") -> ---- | AA35: KK &K | AE35: =+IFERROR(AD35/AB35,"----") -> ---- | AI35: =+IFERROR(AH35/AF35,"----") -> ---- | AM35: =+IFERROR(AL35/AJ35,"----") -> ---- | AQ35: =+IFERROR(AP35/AN35,"----") -> ---- | AU35: =+IFERROR(AT35/AR35,"----") -> ---- | AY35: =+IFERROR(AX35/AV35,"----") -> ---- | AZ35: =B35+F35+J35+N35+R35+V35+AB35+AF35+AJ35+AN35+AR35+AV35 -> 0 | BA35: =C35+G35+K35+O35+S35+W35+AC35+AG35+AK35+AO35+AS35+AW35 -> 0 | BB35: =D35+H35+L35+P35+T35+X35+AD35+AH35+AL35+AP35+AT35+AX35 -> 0 | BC35: =+IFERROR(BB35/AZ35,"----") -> ----
A36: รสดีเด็ด | B36: 100000 | C36: 63204 | D36: 63204 | E36: =+IFERROR(D36/B36,"----") -> 0.63204 | F36: 100000 | G36: 120048.5 | H36: 120048.5 | I36: =+IFERROR(H36/F36,"----") -> 1.200485 | J36: 100000 | K36: 69115 | L36: 69115 | M36: =+IFERROR(L36/J36,"----") -> 0.69115 | N36: 100000 | O36: 66228.5 | P36: 66228.5 | Q36: =+IFERROR(P36/N36,"----") -> 0.662285 | R36: 100000 | S36: 129628 | T36: 129628 | U36: =+IFERROR(T35/R36,"----") -> 0 | V36: 100000 | W36: 70138.5 | X36: 70138.5 | Y36: =+IFERROR(X36/V36,"----") -> 0.701385 | AA36: รสดีเด็ด | AB36: 100000 | AC36: 139874.5 | AD36: 139874.5 | AE36: =+IFERROR(AD36/AB36,"----") -> 1.398745 | AF36: 100000 | AG36: 69989 | AH36: 69989 | AI36: =+IFERROR(AH36/AF36,"----") -> 0.69989 | AJ36: 100000 | AK36: 100000 | AL36: 70219 | AM36: =+IFERROR(AL36/AJ36,"----") -> 0.70219 | AN36: 100000 | AO36: 100000 | AQ36: =+IFERROR(AP36/AN36,"----") -> 0 | AR36: 100000 | AS36: 100000 | AU36: =+IFERROR(AT36/AR36,"----") -> 0 | AV36: 100000 | AW36: 100000 | AY36: =+IFERROR(AX36/AV36,"----") -> 0 | AZ36: =B36+F36+J36+N36+R36+V36+AB36+AF36+AJ36+AN36+AR36+AV36 -> 1200000 | BA36: =C36+G36+K36+O36+S36+W36+AC36+AG36+AK36+AO36+AS36+AW36 -> 1128226 | BB36: =D36+H36+L36+P36+T35+X36+AD36+AH36+AL36+AP36+AT36+AX36 -> 668817 | BC36: =+IFERROR(BB36/AZ36,"----") -> 0.5573475
A37: จาโกต้า | E37: =+IFERROR(D37/B37,"----") -> ---- | I37: =+IFERROR(H37/F37,"----") -> ---- | M37: =+IFERROR(L37/J37,"----") -> ---- | Q37: =+IFERROR(P37/N37,"----") -> ---- | U37: =+IFERROR(T37/R37,"----") -> ---- | Y37: =+IFERROR(X37/V37,"----") -> ---- | AA37: จาโกต้า | AE37: =+IFERROR(AD37/AB37,"----") -> ---- | AI37: =+IFERROR(AH37/AF37,"----") -> ---- | AM37: =+IFERROR(AL37/AJ37,"----") -> ---- | AQ37: =+IFERROR(AP37/AN37,"----") -> ---- | AU37: =+IFERROR(AT37/AR37,"----") -> ---- | AY37: =+IFERROR(AX37/AV37,"----") -> ---- | AZ37: =B37+F37+J37+N37+R37+V37+AB38+AF37+AJ37+AN37+AR37+AV37 -> 300000 | BA37: =C37+G37+K37+O37+S37+W37+AC37+AG37+AK37+AO37+AS37+AW37 -> 0 | BB37: =D37+H37+L37+P37+T37+X37+AD37+AH37+AL37+AP37+AT37+AX37 -> 0 | BC37: =+IFERROR(BB37/AZ37,"----") -> 0
A38: สยามสมุทรวาริน | B38: 300000 | C38: 300000 | D38: 286785.4 | E38: =+IFERROR(D38/B38,"----") -> 0.95595133 | F38: 300000 | G38: 178833.7 | H38: 178833.7 | I38: =+IFERROR(H38/F38,"----") -> 0.59611233 | J38: 200000 | K38: 175301.8 | L38: 175301.8 | M38: =+IFERROR(L38/J38,"----") -> 0.876509 | N38: 200000 | O38: 249892.6 | P38: 249892.6 | Q38: =+IFERROR(P38/N38,"----") -> 1.249463 | R38: 300000 | S38: 324330.9 | T38: 324330.9 | U38: =+IFERROR(T38/R38,"----") -> 1.081103 | V38: 300000 | W38: 373545.7 | X38: 373545.7 | Y38: =+IFERROR(X38/V38,"----") -> 1.2451523 | AA38: สยามสมุทรวาริน | AB38: 300000 | AC38: 70000 | AD38: 64753.35 | AE38: =+IFERROR(AD38/AB38,"----") -> 0.2158445 | AF38: 300000 | AG38: 323280.9 | AH38: 323280.9 | AI38: =+IFERROR(AH38/AF38,"----") -> 1.077603 | AJ38: 300000 | AK38: 260501.7 | AL38: 260501.7 | AM38: =+IFERROR(AL38/AJ38,"----") -> 0.868339 | AN38: 300000 | AO38: 250000 | AQ38: =+IFERROR(AP38/AN38,"----") -> 0 | AR38: 300000 | AS38: 250000 | AU38: =+IFERROR(AT38/AR38,"----") -> 0 | AV38: 300000 | AW38: 250000 | AY38: =+IFERROR(AX38/AV38,"----") -> 0 | AZ38: =B38+F38+J38+N38+R38+V38+AB39+AF38+AJ38+AN38+AR38+AV38 -> 3130000 | BA38: =C38+G38+K38+O38+S38+W38+AC38+AG38+AK38+AO38+AS38+AW38 -> 3005687.3 | BB38: =D38+H38+L38+P38+T38+X38+AD38+AH38+AL38+AP38+AT38+AX38 -> 2237226.1 | BC38: =+IFERROR(BB38/AZ38,"----") -> 0.71476871
A39: ฟู๊ดคลาสสิค | E39: =+IFERROR(D39/B39,"----") -> ---- | G39: 13984 | H39: 13984 | I39: =+IFERROR(H39/F39,"----") -> ---- | J39: 30000 | M39: =+IFERROR(L39/J39,"----") -> 0 | N39: 30000 | O39: 12320 | P39: 12320 | Q39: =+IFERROR(P39/N39,"----") -> 0.41066667 | R39: 30000 | U39: =+IFERROR(T39/R39,"----") -> 0 | V39: 30000 | Y39: =+IFERROR(X39/V39,"----") -> 0 | AA39: ฟู๊ดคลาสสิค | AB39: 30000 | AE39: =+IFERROR(AD39/AB39,"----") -> 0 | AF39: 30000 | AI39: =+IFERROR(AH39/AF39,"----") -> 0 | AJ39: 30000 | AM39: =+IFERROR(AL39/AJ39,"----") -> 0 | AN39: 30000 | AQ39: =+IFERROR(AP39/AN39,"----") -> 0 | AR39: 30000 | AU39: =+IFERROR(AT39/AR39,"----") -> 0 | AV39: 30000 | AY39: =+IFERROR(AX39/AV39,"----") -> 0 | AZ39: =B39+F39+J39+N39+R39+V39+AB39+AF39+AJ39+AN39+AR39+AV39 -> 300000 | BA39: =C39+G39+K39+O39+S39+W39+AC39+AG39+AK39+AO39+AS39+AW39 -> 26304 | BB39: =D39+H39+L39+P39+T39+X39+AD39+AH39+AL39+AP39+AT39+AX39 -> 26304 | BC39: =+IFERROR(BB39/AZ39,"----") -> 0.08768
A40: 786 ฮาลาล | B40: 300000 | C40: 245922.6 | D40: 366226.2 | E40: =+IFERROR(D40/B40,"----") -> 1.220754 | F40: 300000 | G40: 69518.8 | H40: 69518.8 | I40: =+IFERROR(H40/F40,"----") -> 0.23172933 | J40: 300000 | K40: 583510.55 | L40: 583510.55 | M40: =+IFERROR(L40/J40,"----") -> 1.9450352 | N40: 300000 | O40: 177241.25 | P40: 177241.25 | Q40: =+IFERROR(P40/N40,"----") -> 0.59080417 | R40: 300000 | S40: 194903.2 | T40: 194903.2 | U40: =+IFERROR(T40/R40,"----") -> 0.64967733 | V40: 300000 | W40: 280765.95 | X40: 280765.95 | Y40: =+IFERROR(X40/V40,"----") -> 0.9358865 | AA40: 786 ฮาลาล | AB40: 300000 | AC40: 200000 | AD40: 192457.35 | AE40: =+IFERROR(AD40/AB40,"----") -> 0.6415245 | AF40: 300000 | AG40: 241953.1 | AH40: 241953.1 | AI40: =+IFERROR(AH40/AF40,"----") -> 0.80651033 | AJ40: 300000 | AK40: 166957.55 | AL40: 166957.55 | AM40: =+IFERROR(AL40/AJ40,"----") -> 0.55652517 | AN40: 300000 | AO40: 300000 | AQ40: =+IFERROR(AP40/AN40,"----") -> 0 | AR40: 300000 | AS40: 300000 | AU40: =+IFERROR(AT40/AR40,"----") -> 0 | AV40: 300000 | AW40: 300000 | AY40: =+IFERROR(AX40/AV40,"----") -> 0 | AZ40: =B40+F40+J40+N40+R40+V40+AB40+AF40+AJ40+AN40+AR40+AV40 -> 3600000 | BA40: =C40+G40+K40+O40+S40+W40+AC40+AG40+AK40+AO40+AS40+AW40 -> 3060773 | BB40: =D40+H40+L40+P40+T40+X40+AD40+AH40+AL40+AP40+AT40+AX40 -> 2273533.9 | BC40: =+IFERROR(BB40/AZ40,"----") -> 0.63153721
...

Sheet Sheet1
G10: 747007.7
G11: 648042.75
G13: =G10-G11 -> 98964.95
G17: 10090570
G19: 10091492
G23: =G17-G19 -> -922.17

Sheet Graph
B1: Jan | C1: Feb | D1: Mar | E1: Apr | F1: May | G1: Jun | H1: Jul | I1: Aug | J1: Sep | K1: Oct | L1: Nov | M1: Dec
A2: คาดการณ์ เป้าขาย | B2: ='Sales budget performance manage'!B58 -> 15640000 | C2: ='Sales budget performance manage'!F58 -> 25990000 | D2: ='Sales budget performance manage'!J58 -> 25180000 | E2: ='Sales budget performance manage'!N58 -> 25180000 | F2: ='Sales budget performance manage'!R58 -> 25600000 | G2: ='Sales budget performance manage'!V58 -> 25400000 | H2: ='Sales budget performance manage'!AB58 -> 25500000 | I2: ='Sales budget performance manage'!AF58 -> 13500000 | J2: ='Sales budget performance manage'!AJ58 -> 25500000 | K2: ='Sales budget performance manage'!AN58 -> 13500000 | L2: ='Sales budget performance manage'!AR58 -> 13500000 | M2: ='Sales budget performance manage'!AV58 -> 13500000
A3: เป้าขาย | B3: ='Sales budget performance manage'!C58 -> 12130440 | C3: ='Sales budget performance manage'!G58 -> 10090570 | D3: ='Sales budget performance manage'!K58 -> 13632078 | E3: ='Sales budget performance manage'!O58 -> 11152309 | F3: ='Sales budget performance manage'!S58 -> 10607223 | G3: ='Sales budget performance manage'!W58 -> 10052977 | H3: ='Sales budget performance manage'!AC58 -> 14612261 | I3: ='Sales budget performance manage'!AG58 -> 14276665 | J3: ='Sales budget performance manage'!AK58 -> 18239860 | K3: ='Sales budget performance manage'!AO58 -> 14980000 | L3: ='Sales budget performance manage'!AS58 -> 16680000 | M3: ='Sales budget performance manage'!AW58 -> 18380000
A4: ทำได้จริง | B4: ='Sales budget performance manage'!D58 -> 12061304 | C4: ='Sales budget performance manage'!H58 -> 10090570 | D4: ='Sales budget performance manage'!L58 -> 13632078 | E4: ='Sales budget performance manage'!P58 -> 11190029 | F4: ='Sales budget performance manage'!T58 -> 10389285 | G4: ='Sales budget performance manage'!X58 -> 9942527.6 | H4: ='Sales budget performance manage'!AD58 -> 14480069 | I4: ='Sales budget performance manage'!AH58 -> 14377580 | J4: ='Sales budget performance manage'!AL58 -> 11810488 | K4: ='Sales budget performance manage'!AP58 -> 0 | L4: ='Sales budget performance manage'!AT58 -> 0 | M4: =[1]ตามลูกค้า!H6 -> 0
B6: Jan | C6: Feb | D6: Mar | E6: Apr | F6: May | G6: Jun | H6: Jul | I6: Aug | J6: Sep | K6: Oct | L6: Nov | M6: Dec
A7: 2022 | B7: ='Sales budget performance manage'!B115 -> 13199305 | C7: ='Sales budget performance manage'!F115 -> 9795300 | D7: ='Sales budget performance manage'!J115 -> 11183394 | E7: ='Sales budget performance manage'!N115 -> 9996674.9 | F7: ='Sales budget performance manage'!R115 -> 9303906 | G7: ='Sales budget performance manage'!V115 -> 7200000 | H7: ='Sales budget performance manage'!AB115 -> 8709838.8 | I7: ='Sales budget performance manage'!AF115 -> 8628338.1 | J7: ='Sales budget performance manage'!AJ115 -> 6950153.6 | K7: ='Sales budget performance manage'!AN115 -> 9542319.5 | L7: ='Sales budget performance manage'!AR115 -> 10043060 | M7: ='Sales budget performance manage'!AV115 -> 15019156
A8: 2023 | B8: ='Sales budget performance manage'!C115 -> 14495240 | C8: ='Sales budget performance manage'!G115 -> 11085876 | D8: ='Sales budget performance manage'!K115 -> 9097799 | E8: ='Sales budget performance manage'!O115 -> 7373087.6 | F8: ='Sales budget performance manage'!S115 -> 8248722.8 | G8: ='Sales budget performance manage'!W115 -> 7040987.8 | H8: ='Sales budget performance manage'!AC115 -> 9345568.5 | I8: ='Sales budget performance manage'!AG115 -> 9678161.9 | J8: ='Sales budget performance manage'!AK115 -> 8277601.9 | K8: ='Sales budget performance manage'!AO115 -> 9496855.2 | L8: ='Sales budget performance manage'!AS115 -> 9838693 | M8: ='Sales budget performance manage'!AW115 -> 15341310
A9: 2024 | B9: ='Sales budget performance manage'!D115 -> 12061304 | C9: ='Sales budget performance manage'!H115 -> 10090570 | D9: ='Sales budget performance manage'!L115 -> 12984035 | E9: ='Sales budget performance manage'!P115 -> 11190029 | F9: ='Sales budget performance manage'!T115 -> 10259657 | G9: ='Sales budget performance manage'!X115 -> 9942527.6 | H9: ='Sales budget performance manage'!AD115 -> 14480069 | I9: ='Sales budget performance manage'!AH115 -> 14377580 | J9: ='Sales budget performance manage'!AL115 -> 11810488 | K9: ='Sales budget performance manage'!AP115 -> 0 | L9: ='Sales budget performance manage'!AT115 -> 0 | M9: ='Sales budget performance manage'!AX115 -> 0
